Workbook

Sheet Tableau Final
A3: U101/LIMONADE 11,9233 + 9,86 | B3: Quantité | C3: Format | D3: Litrage | E3: Hectolitre
B4: =IFERROR(VLOOKUP("limonade 0,33l",'Quantité roxane'!$A$3:$B$82,2,FALSE),0) -> 0 | C4: 0.33 | D4: =C4*B4 -> 0 | F4: Accises | G4: =ROUND(E10*11.9233,2) -> 6065.14
B5: =IFERROR(VLOOKUP("limonade 0,5l",'Quantité roxane'!$A$3:$B$82,2,FALSE),0) -> 44064 | C5: 0.5 | D5: =C5*B5 -> 22032
B6: =IFERROR(VLOOKUP("limonade 1l",'Quantité roxane'!$A$3:$B$82,2,FALSE),0) -> 0 | C6: 1 | D6: =C6*B6 -> 0
B7: =IFERROR(VLOOKUP("limonade 1,5l",'Quantité roxane'!$A$3:$B$82,2,FALSE),0) -> 18648 | C7: 1.5 | D7: =C7*B7 -> 27972 | F7: Cotisation | G7: =ROUND(E10*9.86,2) -> 5015.58
B8: =IFERROR(VLOOKUP("limonade 2l",'Quantité roxane'!$A$3:$B$82,2,FALSE),0) -> 432 | C8: 2 | D8: =C8*B8 -> 864
B9: =IFERROR(VLOOKUP("limonade 5l",'Quantité roxane'!$A$3:$B$82,2,FALSE),0) -> 0 | C9: 5 | D9: =C9*B9 -> 0
B10: =SUM(B4:B9) -> 63144 | D10: =SUM(D4:D9) -> 50868 | E10: =TRUNC(D10/100,2) -> 508.68 | F10: Total | G10: =SUM(G7,G4) -> 11080.72
A11: U051/EAU 9,86 | B11: Quantité | C11: Format | D11: Litrage | E11: Hectolitre
B12: =IFERROR(VLOOKUP("eau 0,33l",'Quantité roxane'!$A$3:$B$82,2,FALSE),0) -> 161280 | C12: 0.33 | D12: =C12*B12 -> 53222.4 | F12: Cotisation | G12: =ROUND(E21*9.86,2) -> 146183.97
B13: =IFERROR(VLOOKUP("eau 0,5l",'Quantité roxane'!$A$3:$B$82,2,FALSE),0) -> 699624 | C13: 0.5 | D13: =C13*B13 -> 349812
B14: =IFERROR(VLOOKUP("eau 0,75l",'Quantité roxane'!$A$3:$B$82,2,FALSE),0) -> 20568 | C14: 0.75 | D14: =C14*B14 -> 15426
B15: =IFERROR(VLOOKUP("eau 1l",'Quantité roxane'!$A$3:$B$82,2,FALSE),0) -> 2268 | C15: 1 | D15: =C15*B15 -> 2268
B16: =IFERROR(VLOOKUP("eau 1,15l",'Quantité roxane'!$A$3:$B$82,2,FALSE),0) -> 0 | C16: 1.15 | D16: =C16*B16 -> 0
B17: =IFERROR(VLOOKUP("eau 1,25l",'Quantité roxane'!$A$3:$B$82,2,FALSE),0) -> 0 | C17: 1.25 | D17: =C17*B17 -> 0
B18: =IFERROR(VLOOKUP("eau 1,5l",'Quantité roxane'!$A$3:$B$82,2,FALSE),0) -> 515592 | C18: 1.5 | D18: =C18*B18 -> 773388
B19: =IFERROR(VLOOKUP("eau 2l",'Quantité roxane'!$A$3:$B$82,2,FALSE),0) -> 109440 | C19: 2 | D19: =C19*B19 -> 218880
B20: =IFERROR(VLOOKUP("eau 5l",'Quantité roxane'!$A$3:$B$82,2,FALSE),0) -> 13920 | C20: 5 | D20: =C20*B20 -> 69600
B21: =SUM(B12:B20) -> 1522692 | D21: =SUM(D12:D20) -> 1482596.4 | E21: =TRUNC(D21/100,2) -> 14825.96
A22: U050/BONBONNE 1,41 | B22: Quantité | C22: Format | D22: Litrage | E22: Hectolitre | F22: Cotisation | G22: =ROUND(E24*1.41,2) -> 2174.56
B23: =IFERROR(VLOOKUP("bonbonne 18,9l",'Quantité roxane'!$A$3:$B$82,2,FALSE),0) -> 8160 | C23: 18.9 | D23: =C23*B23 -> 154224
B24: =SUM(B23:B23) -> 8160 | D24: =SUM(D23:D23) -> 154224 | E24: =TRUNC(D24/100,2) -> 1542.24
A25: U111/EAU AROMATISÉ SANS SUCRE 6,8133 + 9,86 | B25: Quantité | C25: Format | D25: Litrage | E25: Hectolitre
B26: =IFERROR(VLOOKUP("eau aro 0,33l",'Quantité roxane'!$A$3:$B$82,2,FALSE),0) -> 0 | C26: 0.33 | D26: =C26*B26 -> 0 | F26: Accises | G26: =ROUND(E33*6.8133,2) -> 88.3
B27: =IFERROR(VLOOKUP("eau aro 0,5l",'Quantité roxane'!$A$3:$B$82,2,FALSE),0) -> 2592 | C27: 0.5 | D27: =C27*B27 -> 1296
B28: =IFERROR(VLOOKUP("eau aro 1l",'Quantité roxane'!$A$3:$B$82,2,FALSE),0) -> 0 | C28: 1 | D28: =C28*B28 -> 0
B29: =IFERROR(VLOOKUP("eau aro 1,25l",'Quantité roxane'!$A$3:$B$82,2,FALSE),0) -> 0 | C29: 1.25 | D29: =C29*B29 -> 0
B30: =IFERROR(VLOOKUP("eau aro 1,5l",'Quantité roxane'!$A$3:$B$82,2,FALSE),0) -> 0 | C30: 1.5 | D30: =C30*B30 -> 0 | F30: Cotisation | G30: =ROUND(E33*9.86,2) -> 127.79
B31: =IFERROR(VLOOKUP("eau aro 2l",'Quantité roxane'!$A$3:$B$82,2,FALSE),0) -> 0 | C31: 2 | D31: =C31*B31 -> 0
B32: =IFERROR(VLOOKUP("eau aro 5l",'Quantité roxane'!$A$3:$B$82,2,FALSE),0) -> 0 | C32: 5 | D32: =C32*B32 -> 0
B33: =SUM(B26:B32) -> 2592 | D33: =SUM(D26:D32) -> 1296 | E33: =TRUNC(D33/100,2) -> 12.96
F34: Total | G34: =SUM(G30,G26) -> 216.09
A35: TOTAL des rubriques sans eau +1 | B35: =SUM(B10,B24,B33)+1 -> 73897 | D35: =D10+D21+D24+D33 -> 1688984.4 | E35: =E10+E21+E24+E33 -> 16889.84
C37: Montant Roxane | D37: Diff.
A38: TOTAL Accises | B38: =G4+G26 -> 6153.44 | C38: =SUMIF('Copie fichier roxane'!H2:H301,"Accise Belge",'Copie fichier roxane'!O2:O423) -> 0 | D38: =(B38-C38)/C38 -> #DIV/0! | E38: =C38-B38 -> -6153.44
A39: TOTAL Cotisation | B39: =G7+G12+G22+G30 -> 153501.9 | C39: =SUMIF('Copie fichier roxane'!H2:H301,"Cotisation Emballage",'Copie fichier roxane'!O2:O423) -> 0 | D39: =(B39-C39)/C39 -> #DIV/0! | E39: =C39-B39 -> -153501.9
A40: TOTAL des deux | B40: =SUM(B38:B39) -> 159655.34 | C40: =SUM(C38:C39) -> 0 | D40: =(B40-C40)/C40 -> #DIV/0! | E40: =C40-B40 -> -159655.34
A41: Formalités (12,5EUR/unité) | B41: =12.5*D41 -> 950 | C41: Total BL : | D41: =(COUNT('Quantité roxane'!E3:E567)-'Quantité roxane'!I3) -> 76
A42: Total Général | B42: =SUM(B40:B41) -> 160605.34 | C42: =C40+B41 -> 950

Sheet Détails Tableau
G1: LIMONADE | M1: EAU | V1: BONB. | W1: EAU AROMATISÉ | AD1: TOTAL Roxane | AE1: Vérif. Roxane
A2: N° BL | B2: Date | C2: N°Fac. | D2: Total | E2: Vérif. | G2: 0.33 | H2: 0.5 | I2: 1 | J2: 1.5 | K2: 2 | L2: 5 | M2: 0.33 | N2: 0.5 | O2: 0.75 | P2: 1 | Q2: 1.15 | R2: 1.25 | S2: 1.5 | T2: 2 | U2: 5 | V2: 18.9 | W2: 0.33 | X2: 0.5 | Y2: 1 | Z2: 1.15 | AA2: 1.5 | AB2: 2 | AC2: 5
C3: =VLOOKUP(A3,'[1]Tableau Roxane'!$C$165:$D$251,2,FALSE) -> #N/A | E3: =IF(D3=SUM(G3:AC3),"OK","Erreur") -> OK | F3: 1 | AE3: =IF(D3=AD3,"OK","Erreur") -> OK
E4: =IF(D4=SUM(G4:AC4),"OK","Erreur") -> OK | F4: 2 | AE4: =IF(D4=AD4,"OK","Erreur") -> OK
E5: =IF(D5=SUM(G5:AC5),"OK","Erreur") -> OK | F5: 3 | AE5: =IF(D5=AD5,"OK","Erreur") -> OK
E6: =IF(D6=SUM(G6:AC6),"OK","Erreur") -> OK | F6: 4 | AE6: =IF(D6=AD6,"OK","Erreur") -> OK
E7: =IF(D7=SUM(G7:AC7),"OK","Erreur") -> OK | F7: 5 | AE7: =IF(D7=AD7,"OK","Erreur") -> OK
E8: =IF(D8=SUM(G8:AC8),"OK","Erreur") -> OK | F8: 6 | AE8: =IF(D8=AD8,"OK","Erreur") -> OK
E9: =IF(D9=SUM(G9:AC9),"OK","Erreur") -> OK | F9: 7 | AE9: =IF(D9=AD9,"OK","Erreur") -> OK
E10: =IF(D10=SUM(G10:AC10),"OK","Erreur") -> OK | F10: 8 | AE10: =IF(D10=AD10,"OK","Erreur") -> OK
E11: =IF(D11=SUM(G11:AC11),"OK","Erreur") -> OK | F11: 9 | AE11: =IF(D11=AD11,"OK","Erreur") -> OK
E12: =IF(D12=SUM(G12:AC12),"OK","Erreur") -> OK | F12: 10 | AE12: =IF(D12=AD12,"OK","Erreur") -> OK
E13: =IF(D13=SUM(G13:AC13),"OK","Erreur") -> OK | F13: 11 | AE13: =IF(D13=AD13,"OK","Erreur") -> OK
E14: =IF(D14=SUM(G14:AC14),"OK","Erreur") -> OK | F14: 12 | AE14: =IF(D14=AD14,"OK","Erreur") -> OK
E15: =IF(D15=SUM(G15:AC15),"OK","Erreur") -> OK | F15: 13 | AE15: =IF(D15=AD15,"OK","Erreur") -> OK
... E36: =IF(D36=SUM(G36:AC36),"OK","Erreur") -> OK | F36: 34 | AE36: =IF(D36=AD36,"OK","Erreur") -> OK
E37: =IF(D37=SUM(G37:AC37),"OK","Erreur") -> OK | F37: 35
E38: =IF(D38=SUM(G38:AC38),"OK","Erreur") -> OK | F38: 36
E39: =IF(D39=SUM(G39:AC39),"OK","Erreur") -> OK | F39: 37
E40: =IF(D40=SUM(G40:AC40),"OK","Erreur") -> OK | F40: 38
E41: =IF(D41=SUM(G41:AC41),"OK","Erreur") -> OK | F41: 39
E42: =IF(D42=SUM(G42:AC42),"OK","Erreur") -> OK | F42: 40
E43: =IF(D43=SUM(G43:AC43),"OK","Erreur") -> OK | F43: 41
E44: =IF(D44=SUM(G44:AC44),"OK","Erreur") -> OK | F44: 42
E45: =IF(D45=SUM(G45:AC45),"OK","Erreur") -> OK | F45: 43
E46: =IF(D46=SUM(G46:AC46),"OK","Erreur") -> OK | F46: 44
E47: =IF(D47=SUM(G47:AC47),"OK","Erreur") -> OK | F47: 45
E48: =IF(D48=SUM(G48:AC48),"OK","Erreur") -> OK | F48: 46
... E78: =IF(D78=SUM(G78:AC78),"OK","Erreur") -> OK | F78: 76
E79: =IF(D79=SUM(G79:AC79),"OK","Erreur") -> OK | F79: 77 | AE79: =IF(D79=AD79,"OK","Erreur") -> OK
E80: =IF(D80=SUM(G80:AC80),"OK","Erreur") -> OK | F80: 78 | AE80: =IF(D80=AD80,"OK","Erreur") -> OK
E81: =IF(D81=SUM(G81:AC81),"OK","Erreur") -> OK | F81: 79 | AE81: =IF(D81=AD81,"OK","Erreur") -> OK
E82: =IF(D82=SUM(G82:AC82),"OK","Erreur") -> OK | F82: 80 | AE82: =IF(D82=AD82,"OK","Erreur") -> OK
E83: =IF(D83=SUM(G83:AC83),"OK","Erreur") -> OK | F83: 81 | AE83: =IF(D83=AD83,"OK","Erreur") -> OK
E84: =IF(D84=SUM(G84:AC84),"OK","Erreur") -> OK | F84: 82 | AE84: =IF(D84=AD84,"OK","Erreur") -> OK
E85: =IF(D85=SUM(G85:AC85),"OK","Erreur") -> OK | F85: 83 | AE85: =IF(D85=AD85,"OK","Erreur") -> OK
E86: =IF(D86=SUM(G86:AC86),"OK","Erreur") -> OK | F86: 84 | AE86: =IF(D86=AD86,"OK","Erreur") -> OK
E87: =IF(D87=SUM(G87:AC87),"OK","Erreur") -> OK | F87: 85 | AE87: =IF(D87=AD87,"OK","Erreur") -> OK
E88: =IF(D88=SUM(G88:AC88),"OK","Erreur") -> OK | F88: 86 | AE88: =IF(D88=AD88,"OK","Erreur") -> OK
E89: =IF(D89=SUM(G89:AC89),"OK","Erreur") -> OK | F89: 87 | AE89: =IF(D89=AD89,"OK","Erreur") -> OK
...

Sheet Procédure avec fichier roxane
A1: Etape 1 : | B1: - Copier le tableau de Roxane dans le fichier de la semaine en cours
B2: - Clique droit sur l'onglet pour copier facilement
A4: Etape 2 : | B4: - Filtrer uniquement les accises (colonne H) et copier la somme (la valeur uniquement) de la colonne HTECOT
B5: dans l'onglet tableau final, cellule C38
B6: - Supprimer les lignes des accises
A8: Etape 3 : | B8: Copier la somme ( la valeur uniquement) de la colonne HTECOT ( il reste uniquement les cotisations emballage)
B9: dans l'onglet tableau final, cellule C39
A11: Etape 4 : | B11: Filtrer la colonne LIBFAM, K
B12: Pour chaque type de produit, changer la dénomination par le type de produit et le format
B13: Se référer à l'onglet "Catégorie Articles Roxane"
B15: EXEMPLE : | C15: BOISSON JUS FRAISE 0L50 PET | F15: en | G15: sucré 0,5 l
C16: E.D.S. SPORT CAP 0L33 PET | F16: en | G16: eau 0,33 l
A19: Etape 5 : | B19: Créer un tableau dynamique
B20: Afficher Nombre de bouteilles par catégorie
B21: Mettre les sommes en milliers
B22: - Aller sur le tableau de Roxane
B23: - Onglet Insertion - Tableau Croisé - Dynamique
A37: Etape 6 : | B37: Encoder le résultat dans l'onglet Tableau Final
B38: Verifier si les sommes correspondent aux sommes de Roxane
B39: Si pas, refaire la procédure en s'assurant que les catégories soient corrects
A41: Etape 7 : | B41: Afficher le détail et calculer le nombre de BL
E44: Compter le nombre de Factures correspondant au nombre de BL à indiquer
E45: dans l'onglet Tableau Final , cellule D41
E48: Imprimer le détail sur une page pour envoyer à Roxane
A62: Etape 8 : | B62: Imprimer le tableau final sur une page
B63: Envoyer le montant à payer à Roxane

Sheet Catégorie Articles Roxane
A1: Description | B1: Catégorie | D1: LIMONADE | J1: EAU | S1: BONB. | T1: EAU AROMATISÉ
A2: EMGA CORA CITRON | B2: Aro | D2: 0.33 | E2: 0.5 | F2: 1 | G2: 1.5 | H2: 2 | I2: 5 | J2: 0.33 | K2: 0.5 | L2: 0.75 | M2: 1 | N2: 1.15 | O2: 1.25 | P2: 1.5 | Q2: 2 | R2: 5 | S2: 18.9 | T2: 0.33 | U2: 0.5 | V2: 1 | W2: 1.15 | X2: 1.5 | Y2: 2 | Z2: 5
A3: EMGA Menthe | B3: Aro | E3: BOISSON JUS FRAISE 0L50 PET | G3: BOISSON JUS FRAISE 1L50 PET | H3: B.A.J. EXOTIQUE 12% 2L00 SUCRE (LIDL) | J3: E.D.S. PLATE 0L33 PET | K3: E.D.S. GAZ PETILLANTE 0L50 PET | L3: E.D.S. SPORT CAP 0L75 PET | M3: EMG 1L00 PET | P3: E.D.S MONTAGNE 1L50 PET | Q3: E.D.S. PLATE 2L00 PET | R3: E.D.S. PLATE 5L00 PET | S3: BONBONNE CLIENT 18L9 | U3: E.M.G. AROME 0L50 PET | X3: E.M.P ARO CITRON 1L50 PET
A4: Celestins | B4: Eau | E4: BOISSON JUS PECHE 0L50 PET | G4: BOISSON JUS TROPICAL 1L50 PET | J4: E.D.S. SPORT CAP 0L33 PET | K4: E.D.S. PLATE 0L50 PET | M4: E.D.S. PLATE 1L00 PET | P4: E.D.S. GAZ PETIL 1L50 BTE VERTE | U4: E.D.S. ARO CITRON 0L50 SS SUCRE
A5: EM LEG GAZ | B5: Eau | E5: BOISSON JUS TROPICAL 0L50 PET | G5: E.D.S. ARO FR ROUGES 1L5 (SUCRALOSE) | J5: E.M. PLATE 33CL SPORT | K5: E.M.G. 0L50 PET | M5: E.M. PLATE 1L00 PET | P5: E.D.S. PLATE 1L50 PET
A6: Aro Fraise Cora Kido | B6: Limonade | E6: E.D.S. ARO FRUITS ROUGES 0L50 PET | G6: B.A.J. EXOTIQUE 12% 1L50 PET | K6: E.M. PLATE 0L50 PET | M6: EAU SOURCE GAZ 1L00 | P6: E.M. PLATE 1L50 PET
A7: Aro Peche Cora Kido | B7: Limonade | G7: SODA ORANGE 6% JUS 1L5 BTE CARREFOUR | K7: E.D.S. MONTAGNE PLATE 0L50 PET | P7: E.M.G. FINE GAZ 1L50 PET
A8: Cola | B8: Limonade | G8: GRENADINE 1L5 BTE CARREFOUR (PS) | K8: E.M. PLATE 0L50 SPORT PET | P8: E.M.G. 1L50 PET
A9: Fruits rouges | B9: Limonade | G9: SODA ORANGE 1L5 PET BTE CARREFOUR
A10: Grenadine | B10: Limonade | G10: COLA REG 1L5 BTE CARREFOUR
A11: Jus | B11: Limonade | G11: LIMONADE 1L5 STD BTE CARREFOUR
A12: Orange 6 % | B12: Limonade | G12: SODA ORANGE 6% JUS 1L5 BTE CARREFOUR
A13: Soda | B13: Limonade
A14: The vert menthe | B14: Limonade
A15: Tropical | B15: Limonade
A16: Cristaline ARO Citron | B16: Aro
D17: limonade 0,33l | E17: limonade 0,5l | F17: limonade 1l | G17: limonade 1,5l | H17: limonade 2l | I17: limonade 5l | J17: eau 0,33l | K17: eau 0,5l | L17: eau 0,75l | M17: eau 1l | N17: eau 1,15l | O17: eau 1,25l | P17: eau 1,5l | Q17: eau 2l | R17: eau 5l | S17: bonbonne 18,9l | T17: eau aro 0,33l | U17: eau aro 0,5l | V17: eau aro 1l | W17: eau aro 1,15l | X17: eau aro 1,5l | Y17: eau aro 2l | Z17: eau aro 5l
D19: N° | E19: Description Roxane | F19: Description
A20: 1 | B20: limonade 0,33l | D20: 2 | E20: BOISSON JUS FRAISE 0L50 PET | F20: =LOOKUP(D20,$A$20:$A$42,$B$20:$B$42) -> limonade 0,5l
A21: 2 | B21: limonade 0,5l | D21: 2 | E21: BOISSON JUS PECHE 0L50 PET | F21: =LOOKUP(D21,$A$20:$A$42,$B$20:$B$42) -> limonade 0,5l
A22: 3 | B22: limonade 1l | D22: 2 | E22: BOISSON JUS TROPICAL 0L50 PET | F22: =LOOKUP(D22,$A$20:$A$42,$B$20:$B$42) -> limonade 0,5l
A23: 4 | B23: limonade 1,5l | D23: 2 | E23: E.D.S. ARO FRUITS ROUGES 0L50 PET | F23: =LOOKUP(D23,$A$20:$A$42,$B$20:$B$42) -> limonade 0,5l
A24: 5 | B24: limonade 2l | D24: 4 | E24: BOISSON JUS FRAISE 1L50 PET | F24: =LOOKUP(D24,$A$20:$A$42,$B$20:$B$42) -> limonade 1,5l
A25: 6 | B25: limonade 5l | D25: 4 | E25: BOISSON JUS TROPICAL 1L50 PET | F25: =LOOKUP(D25,$A$20:$A$42,$B$20:$B$42) -> limonade 1,5l
A26: 7 | B26: eau 0,33l | D26: 4 | E26: E.D.S. ARO FR ROUGES 1L5 (SUCRALOSE) | F26: =LOOKUP(D26,$A$20:$A$42,$B$20:$B$42) -> limonade 1,5l
A27: 8 | B27: eau 0,5l | D27: 4 | E27: B.A.J. EXOTIQUE 12% 1L50 PET | F27: =LOOKUP(D27,$A$20:$A$42,$B$20:$B$42) -> limonade 1,5l
A28: 9 | B28: eau 0,75l | D28: 4 | E28: SODA ORANGE 6% JUS 1L5 BTE CARREFOUR | F28: =LOOKUP(D28,$A$20:$A$42,$B$20:$B$42) -> limonade 1,5l
A29: 10 | B29: eau 1l | D29: 4 | E29: GRENADINE 1L5 BTE CARREFOUR (PS) | F29: =LOOKUP(D29,$A$20:$A$42,$B$20:$B$42) -> limonade 1,5l
A30: 11 | B30: eau 1,15l | D30: 4 | E30: SODA ORANGE 1L5 PET BTE CARREFOUR | F30: =LOOKUP(D30,$A$20:$A$42,$B$20:$B$42) -> limonade 1,5l
A31: 12 | B31: eau 1,25l | D31: 4 | E31: COLA REG 1L5 BTE CARREFOUR | F31: =LOOKUP(D31,$A$20:$A$42,$B$20:$B$42) -> limonade 1,5l
... A42: 23 | B42: eau aro 5l | D42: 8 | E42: E.M. PLATE 0L50 SPORT PET | F42: =LOOKUP(D42,$A$20:$A$42,$B$20:$B$42) -> eau 0,5l
D43: 9 | E43: E.D.S. SPORT CAP 0L75 PET | F43: =LOOKUP(D43,$A$20:$A$42,$B$20:$B$42) -> eau 0,75l
D44: 10 | E44: EMG 1L00 PET | F44: =LOOKUP(D44,$A$20:$A$42,$B$20:$B$42) -> eau 1l
D45: 10 | E45: E.D.S. PLATE 1L00 PET | F45: =LOOKUP(D45,$A$20:$A$42,$B$20:$B$42) -> eau 1l
D46: 10 | E46: E.M. PLATE 1L00 PET | F46: =LOOKUP(D46,$A$20:$A$42,$B$20:$B$42) -> eau 1l
D47: 10 | E47: EAU SOURCE GAZ 1L00 | F47: =LOOKUP(D47,$A$20:$A$42,$B$20:$B$42) -> eau 1l
D48: 13 | E48: E.D.S MONTAGNE 1L50 PET | F48: =LOOKUP(D48,$A$20:$A$42,$B$20:$B$42) -> eau 1,5l
D49: 13 | E49: E.D.S. GAZ PETIL 1L50 BTE VERTE | F49: =LOOKUP(D49,$A$20:$A$42,$B$20:$B$42) -> eau 1,5l
D50: 13 | E50: E.D.S. PLATE 1L50 PET | F50: =LOOKUP(D50,$A$20:$A$42,$B$20:$B$42) -> eau 1,5l
D51: 13 | E51: E.M. PLATE 1L50 PET | F51: =LOOKUP(D51,$A$20:$A$42,$B$20:$B$42) -> eau 1,5l
...

Sheet Copie fichier roxane
A1: SITDEP | B1: FANFAC | C1: FANLIV | D1: FADAEM | E1: FACLFA | F1: FACLLV | G1: TYPTAX | H1: LIBTAX | I1: FANART | J1: FACOND | K1: LIBFAM | L1: FAQTUC | M1: FAQTFA | N1: PUECOT | O1: HTECOT | P1: FAMILLE | Q1: CODTAX | R1: LIBSEC | S1: DATCALC | T1: Désignation
T2: =VLOOKUP(K2,'Catégorie Articles Roxane'!$E$20:$F$600,2,FALSE) -> #N/A
T3: =VLOOKUP(K3,'Catégorie Articles Roxane'!$E$20:$F$600,2,FALSE) -> #N/A
T4: =VLOOKUP(K4,'Catégorie Articles Roxane'!$E$20:$F$600,2,FALSE) -> #N/A
T5: =VLOOKUP(K5,'Catégorie Articles Roxane'!$E$20:$F$600,2,FALSE) -> #N/A
T6: =VLOOKUP(K6,'Catégorie Articles Roxane'!$E$20:$F$600,2,FALSE) -> #N/A
T7: =VLOOKUP(K7,'Catégorie Articles Roxane'!$E$20:$F$600,2,FALSE) -> #N/A
T8: =VLOOKUP(K8,'Catégorie Articles Roxane'!$E$20:$F$600,2,FALSE) -> #N/A
T9: =VLOOKUP(K9,'Catégorie Articles Roxane'!$E$20:$F$600,2,FALSE) -> #N/A
T10: =VLOOKUP(K10,'Catégorie Articles Roxane'!$E$20:$F$600,2,FALSE) -> #N/A
T11: =VLOOKUP(K11,'Catégorie Articles Roxane'!$E$20:$F$600,2,FALSE) -> #N/A
T12: =VLOOKUP(K12,'Catégorie Articles Roxane'!$E$20:$F$600,2,FALSE) -> #N/A
T13: =VLOOKUP(K13,'Catégorie Articles Roxane'!$E$20:$F$600,2,FALSE) -> #N/A
... T473: =VLOOKUP(K473,'Catégorie Articles Roxane'!$E$20:$F$600,2,FALSE) -> #N/A

Sheet Quantité roxane
A1: Étiquettes de lignes | B1: Somme de FAQTFA | E1: Somme de HTECOT | F1: Étiquettes de colonnes
A2: Accise Belge | B2: 65736 | E2: Étiquettes de lignes | F2: Cotisation Emballage | G2: Total général | I2: Nbr BL montant négatif
A3: eau aro 0,5l | B3: 2592 | E3: 14131 | F3: 2271.74 | G3: 2271.74 | H3: =IF(F3="","",IF(F3<=0,"1","")) | I3: =COUNTIF(H3:H620,1) -> 0
A4: limonade 0,5l | B4: 44064 | E4: 73386 | F4: 2385.33 | G4: 2385.33 | H4: =IF(F4="","",IF(F4<=0,"1",""))
A5: limonade 1,5l | B5: 18648 | E5: 96594 | F5: 2340.36 | G5: 2340.36 | H5: =IF(F5="","",IF(F5<=0,"1",""))
A6: limonade 2l | B6: 432 | E6: 14133 | F6: 2176.2 | G6: 2176.2 | H6: =IF(F6="","",IF(F6<=0,"1",""))
A7: Cotisation Emballage | B7: 1596588 | E7: 96760 | F7: 2289.88 | G7: 2289.88 | H7: =IF(F7="","",IF(F7<=0,"1",""))
A8: bonbonne 18,9l | B8: 8160 | E8: 24008 | F8: 2603.04 | G8: 2603.04 | H8: =IF(F8="","",IF(F8<=0,"1",""))
A9: eau 1,5l | B9: 515592 | E9: 86846 | F9: 2236.25 | G9: 2236.25 | H9: =IF(F9="","",IF(F9<=0,"1",""))
A10: eau 2l | B10: 109440 | E10: 97049 | F10: 2300.14 | G10: 2300.14 | H10: =IF(F10="","",IF(F10<=0,"1",""))
A11: eau 5l | B11: 13920 | E11: 97083 | F11: 2271.74 | G11: 2271.74 | H11: =IF(F11="","",IF(F11<=0,"1",""))
A12: eau aro 0,5l | B12: 2592 | E12: 97125 | F12: 2300.14 | G12: 2300.14 | H12: =IF(F12="","",IF(F12<=0,"1",""))
A13: limonade 0,5l | B13: 44064 | E13: 97131 | F13: 2332.49 | G13: 2332.49 | H13: =IF(F13="","",IF(F13<=0,"1",""))
A14: limonade 1,5l | B14: 18648 | E14: 97135 | F14: 2366.4 | G14: 2366.4 | H14: =IF(F14="","",IF(F14<=0,"1",""))
A15: eau 0,5l | B15: 699624 | E15: 97139 | F15: 2310.79 | G15: 2310.79 | H15: =IF(F15="","",IF(F15<=0,"1",""))
... A20: Total général | B20: 1662324 | E20: 71177 | F20: 2236.25 | G20: 2236.25 | H20: =IF(F20="","",IF(F20<=0,"1",""))
E21: 71185 | F21: 294.22 | G21: 294.22 | H21: =IF(F21="","",IF(F21<=0,"1",""))
E22: 71197 | F22: 2236.25 | G22: 2236.25 | H22: =IF(F22="","",IF(F22<=0,"1",""))
E23: 14502 | F23: 2271.74 | G23: 2271.74 | H23: =IF(F23="","",IF(F23<=0,"1",""))
E24: 14567 | F24: 2271.74 | G24: 2271.74 | H24: =IF(F24="","",IF(F24<=0,"1",""))
E25: 14574 | F25: 2555.71 | G25: 2555.71 | H25: =IF(F25="","",IF(F25<=0,"1",""))
E26: 6247 | F26: 2044.57 | G26: 2044.57 | H26: =IF(F26="","",IF(F26<=0,"1",""))
E27: 92024 | F27: 2293.2 | G27: 2293.2 | H27: =IF(F27="","",IF(F27<=0,"1",""))
E28: 24108 | F28: 2108.46 | G28: 2108.46 | H28: =IF(F28="","",IF(F28<=0,"1",""))
E29: 24196 | F29: 351.41 | G29: 351.41 | H29: =IF(F29="","",IF(F29<=0,"1",""))
E30: 97171 | F30: 2310.79 | G30: 2310.79 | H30: =IF(F30="","",IF(F30<=0,"1",""))
E31: 97175 | F31: 2300.14 | G31: 2300.14 | H31: =IF(F31="","",IF(F31<=0,"1",""))
E32: 97194 | F32: 2285.53 | G32: 2285.53 | H32: =IF(F32="","",IF(F32<=0,"1",""))
... E78: 73679 | F78: 2385.33 | G78: 2385.33 | H78: =IF(F78="","",IF(F78<=0,"1",""))
E79: Total général | F79: 154225.02 | G79: 154225.02 | H79: =IF(F79="","",IF(F79<=0,"1",""))
H80: =IF(F80="","",IF(F80<=0,"1",""))
H81: =IF(F81="","",IF(F81<=0,"1",""))
H82: =IF(F82="","",IF(F82<=0,"1",""))
H83: =IF(F83="","",IF(F83<=0,"1",""))
H84: =IF(F84="","",IF(F84<=0,"1",""))
H85: =IF(F85="","",IF(F85<=0,"1",""))
H86: =IF(F86="","",IF(F86<=0,"1",""))
H87: =IF(F87="","",IF(F87<=0,"1",""))
H88: =IF(F88="","",IF(F88<=0,"1",""))
H89: =IF(F89="","",IF(F89<=0,"1",""))
...
