Workbook

Sheet Données Bruts
A1: N°Support | B1: N°Article | C1: Désignation | D1: Composition | E1: EAN | F1: EAN | G1: EAN | H1: Pays Origine | I1: Code Douane | J1: Colisage | K1: #Colis | L1: #Pces | M1: Poids Brut | N1: Poids Net | O1: Vol. Pce | P1: Vol.Total | Q1: PA Unitaire | R1: PA Global
A2: 18768943 | B2: 905236 | C2: HR Sabot injecté db chaud Fushia 36/41 | H2: CN | I2: 64029910 | J2: 1 | K2: 16 | L2: 16 | M2: 4.266 | N2: 3.84 | O2: 5.136 | P2: 82.176 | Q2: 3.68 | R2: 58.82
A3: 18768943 | B3: 997529 | C3: HR panty fant D formes | H3: CN | I3: 61152200 | J3: 5 | K3: 4 | L3: 20 | M3: 1.48 | N3: 1.332 | O3: 0.617 | P3: 12.34 | Q3: 1.86 | R3: 37.2
A4: 18768943 | B4: 991982 | C4: PR 0CM4 CO ULTRA RESIST TRANSP 20 D NOIR | H4: CN | I4: 61152200 | J4: 12 | K4: 3 | L4: 36 | M4: 1.86 | N4: 1.674 | O4: 0.633 | P4: 22.776 | Q4: 4.01 | R4: 144.36
A5: 18768943 | B5: 709775 | C5: HR panty Golden Lady liberté abs silhou | H5: IT | I5: 61152200 | J5: 12 | K5: 3 | L5: 36 | M5: 2.352 | N5: 2.117 | O5: 0.76 | P5: 27.36 | Q5: 3.71 | R5: 133.56
A6: 18768943 | B6: 793513 | C6: HR panty fant D POIS | H6: CN | I6: 61152100 | J6: 4 | K6: 4 | L6: 16 | M6: 1.14 | N6: 1.026 | O6: 0.781 | P6: 12.496 | Q6: 1.67 | R6: 26.64
A7: 18768943 | B7: 723185 | C7: HR Ultra fine Hebdo 4 paires 42/43 | E7: 3031446805734 | H7: BE | I7: 64069050 | J7: 3 | K7: 1 | L7: 3 | M7: 0.234 | N7: 0.211 | O7: 1 | P7: 3 | Q7: 2.71 | R7: 8.13
A8: 18768943 | B8: 996593 | C8: HR ULTRA FINE HEBDO 2 PAIRES 38/39 | E8: 3031446805765 | H8: BE | I8: 64069050 | J8: 3 | K8: 1 | L8: 3 | M8: 0.186 | N8: 0.167 | O8: 0.75 | P8: 2.25 | Q8: 1.39 | R8: 4.17
A9: 18768943 | B9: 929409 | C9: HR Protection froid 38/39 | E9: 3031446801743 | H9: BE | I9: 64069050 | J9: 3 | K9: 1 | L9: 3 | M9: 0.084 | N9: 0.076 | O9: 0.418 | P9: 1.254 | Q9: 2.11 | R9: 6.33
A10: 18768943 | B10: 723182 | C10: HR Ultra fine Hebdo 4 paires 40/41 | E10: 3031446805727 | H10: BE | I10: 64069050 | J10: 3 | K10: 1 | L10: 3 | M10: 0.219 | N10: 0.197 | O10: 1 | P10: 3 | Q10: 2.71 | R10: 8.13
A11: 18768943 | B11: 723168 | C11: HR Ultra fine Hebdo 4 paires 44/45 | E11: 3031446805741 | H11: BE | I11: 64069050 | J11: 3 | K11: 1 | L11: 3 | M11: 0.252 | N11: 0.227 | O11: 1 | P11: 3 | Q11: 2.71 | R11: 8.13
A12: 18768943 | B12: 996600 | C12: HR ULTRA FINE HEBDO 2 PAIRES 36/37 | E12: 3031446805758 | H12: BE | I12: 64069050 | J12: 3 | K12: 1 | L12: 3 | M12: 0.186 | N12: 0.167 | O12: 0.75 | P12: 2.25 | Q12: 1.39 | R12: 4.17
A13: 18768943 | B13: 763302 | C13: HR SS-GENE DB COTON BIO NOIR 40/46 | H13: ES | I13: 64041910 | J13: 2 | K13: 7 | L13: 14 | M13: 9.12 | N13: 8.208 | O13: 4.341 | P13: 60.774 | Q13: 4.55 | R13: 63.7
A14: 18768943 | B14: 763301 | C14: HR SS-GENE DB LAINE BIO NOIR 40/46 | H14: ES | I14: 64041910 | J14: 2 | K14: 6 | L14: 12 | M14: 7.872 | N14: 7.084 | O14: 4.135 | P14: 49.624 | Q14: 4.47 | R14: 53.66
A15: 18768943 | B15: 905233 | C15: HR Sabot injecté db chaud Marine 41/46 | H15: CN | I15: 64029910 | J15: 1 | K15: 16 | L15: 16 | M15: 5.637 | N15: 5.074 | O15: 6.918 | P15: 110.68 | Q15: 4.04 | R15: 64.62
A16: 18768943 | B16: 905234 | C16: HR Sabot injecté db chaud Noir 36/41 | H16: CN | I16: 64029910 | J16: 1 | K16: 12 | L16: 12 | M16: 3.21 | N16: 2.891 | O16: 5.036 | P16: 60.428 | Q16: 3.08 | R16: 36.96
A17: 18768943 | B17: 905231 | C17: HR Sabot injecté db chaud Noir 41/46 | H17: CN | I17: 64029910 | J17: 1 | K17: 16 | L17: 16 | M17: 5.496 | N17: 4.947 | O17: 6.902 | P17: 110.424 | Q17: 3.66 | R17: 58.51
A18: 18768943 | B18: 905235 | C18: HR Sabot injecté db chaud Gris 36/41 | H18: CN | I18: 64029910 | J18: 1 | K18: 12 | L18: 12 | M18: 3.226 | N18: 2.905 | O18: 5.198 | P18: 62.38 | Q18: 3.25 | R18: 38.94
A19: 18832507 | B19: 901451 | C19: BROCHURE D'ACCUEIL | H19: BE | I19: 48211010 | J19: 1 | K19: 5 | L19: 5 | M19: 0.15 | N19: 0.135 | O19: 0.157 | P19: 0.785 | Q19: 2 | R19: 10
A20: 18832507 | B20: 900850 | C20: EVERYDAY CREME A CAFE (CUPS) 20 X 10 GR | E20: 5400141167900 | H20: DE | I20: 4015011 | J20: 1 | K20: 5 | L20: 5 | M20: 1.145 | N20: 1.031 | O20: 0.746 | P20: 3.73 | Q20: 0.58 | R20: 2.9
A21: 18832507 | B21: 900216 | C21: B/100 FEUILLES ETIQUET. PALETTE POUBELLE | H21: BE | I21: 48219010 | J21: 1 | K21: 1 | L21: 1 | M21: 0.01 | N21: 0.009 | O21: 0.45 | P21: 0.45 | Q21: 11.02 | R21: 11.02
A22: 18832507 | B22: 900774 | C22: CARTON AMERICAIN | H22: FR | I22: 48191000 | J22: 10 | K22: 5 | L22: 50 | M22: 10 | N22: 9 | O22: 8.55 | P22: 427.5 | Q22: 2.58 | R22: 129
A23: 18832507 | B23: 901050 | C23: BONI ASSORTIMENT MELANGE 500GR | H23: BE | I23: 19053199 | J23: 1 | K23: 5 | L23: 5 | M23: 3.13 | N23: 2.817 | O23: 2.97 | P23: 14.85 | Q23: 2.85 | R23: 14.25
A24: 18832507 | B24: 900781 | C24: MAXI SACS | H24: FR | I24: 39232100 | J24: 25 | K24: 3 | L24: 75 | M24: 25.125 | N24: 22.613 | O24: 3 | P24: 225 | Q24: 1.22 | R24: 91.5
A25: 18832517 | B25: 915273 | C25: EDP 50ML. ORIENTAL | E25: 8715658440048 | H25: CN | I25: 33030010 | J25: 1 | K25: 2 | L25: 2 | M25: 2.424 | N25: 2.182 | O25: 4 | P25: 8 | Q25: 1.83 | R25: 3.66
A26: 18832517 | B26: 283973 | C26: BYPHASSE DISSOLVANT 250ML ESSENTIALS | E26: 8436097092703 | F26: 8437005723306 | G26: 8436097093984 | H26: ES | I26: 33043000 | J26: 1 | K26: 5 | L26: 5 | M26: 1.335 | N26: 1.202 | O26: 0.507 | P26: 2.535 | Q26: 0.69 | R26: 3.45
A27: 18832651 | B27: 700322 | C27: PR JEANS REGULAR FIT DENIM NOIR | H27: BD | I27: 62046390 | J27: 1 | K27: 1 | L27: 1 | M27: 0.471 | N27: 0.424 | O27: 2.533 | P27: 2.533 | Q27: 7.47 | R27: 7.47
A28: 18832651 | B28: 991150 | C28: PR CEINT DGT NOIR Silver | H28: CN | I28: 39262000 | J28: 2 | K28: 1 | L28: 2 | M28: 0.244 | N28: 0.22 | O28: 0.442 | P28: 0.884 | Q28: 1.05 | R28: 2.1
A29: 18832651 | B29: 659963 | C29: PR PANT DROIT STRETCH GRIS | H29: BD | I29: 62046290 | J29: 1 | K29: 1 | L29: 1 | M29: 0.497 | N29: 0.447 | O29: 3 | P29: 3 | Q29: 7.93 | R29: 7.93
A30: 18832651 | B30: 635597 | C30: PR LEGGING LONG NOIR | H30: IN | I30: 61152900 | J30: 2 | K30: 1 | L30: 2 | M30: 0.334 | N30: 0.301 | O30: 1.386 | P30: 2.772 | Q30: 2.58 | R30: 5.16
A31: 18832651 | B31: 942303 | C31: HR LEGGING DARK GREY MEL | H31: IN | I31: 61142000 | J31: 2 | K31: 1 | L31: 2 | M31: 0.352 | N31: 0.317 | O31: 1.176 | P31: 2.352 | Q31: 2.55 | R31: 5.1
A32: 18832651 | B32: 700245 | C32: HR Cardigan Polar ftte turquoise | H32: BD | I32: 61109090 | J32: 1 | K32: 1 | L32: 1 | M32: 0.136 | N32: 0.122 | O32: 1.8 | P32: 1.8 | Q32: 2.86 | R32: 2.86
A33: 18832651 | B33: 700243 | C33: HR Cardigan Polar ftte bleu nuit | H33: BD | I33: 61109090 | J33: 1 | K33: 1 | L33: 1 | M33: 0.204 | N33: 0.184 | O33: 2.4 | P33: 2.4 | Q33: 2.93 | R33: 2.93
A34: 18832651 | B34: 700247 | C34: HR Cardigan Polar fille rose | H34: BD | I34: 61109090 | J34: 1 | K34: 1 | L34: 1 | M34: 0.333 | N34: 0.3 | O34: 2.666 | P34: 2.666 | Q34: 3.6 | R34: 3.6
A35: 18832651 | B35: 380893 | C35: PR tshirt fines brides cot-ea noir | H35: IN | I35: 61091000 | J35: 2 | K35: 1 | L35: 2 | M35: 0.224 | N35: 0.202 | O35: 1.2 | P35: 2.4 | Q35: 1.03 | R35: 2.06
A36: 18832651 | B36: 991151 | C36: PR CEINT DGT CAMEL Gold | H36: CN | I36: 39262000 | J36: 2 | K36: 1 | L36: 2 | M36: 0.24 | N36: 0.216 | O36: 0.442 | P36: 0.884 | Q36: 1.05 | R36: 2.1
A37: 18832651 | B37: 745081 | C37: PR CARDIGAN MOLLETON VIEUX ROSE | H37: PK | I37: 61101990 | J37: 2 | K37: 1 | L37: 2 | M37: 0.86 | N37: 0.774 | O37: 3.52 | P37: 7.04 | Q37: 4.77 | R37: 9.54
A38: 18832651 | B38: 380904 | C38: HR Polar cintré full zip NOIR | H38: CN | I38: 61103010 | J38: 1 | K38: 1 | L38: 1 | M38: 0.35 | N38: 0.315 | O38: 3.3 | P38: 3.3 | Q38: 5.6 | R38: 5.6
... A58: 18832651 | B58: 707862 | C58: HR Collant micro Fille LiLi Marine | H58: PL | I58: 61152100 | J58: 3 | K58: 1 | L58: 3 | M58: 0.129 | N58: 0.116 | O58: 0.455 | P58: 1.365 | Q58: 0.87 | R58: 2.61
A59: 18832651 | B59: 991176 | C59: PT lot 3 culottes Frozen | E59: 8720193921013 | H59: CN | I59: 61082100 | J59: 12 | K59: 1 | L59: 12 | M59: 0.852 | N59: 0.767 | O59: 0.585 | P59: 7.02 | Q59: 1.78 | R59: 21.36
...

Sheet Combiner
A1: N°Support | B1: N°Article | C1: Désignation | D1: Composition | E1: EAN | F1: EAN | G1: EAN | H1: Conca Valeur | I1: Colisage | J1: #Colis | K1: #Pces | L1: Poids Brut | M1: Poids Net | N1: Vol. Pce | O1: Vol.Total | P1: PA Unitaire | Q1: PA Global
A2: 18768943 | B2: 905236 | C2: HR Sabot injecté db chaud Fushia 36/41 | H2: CN64029910 | I2: 1 | J2: 16 | K2: 16 | L2: 4.266 | M2: 3.84 | N2: 5.136 | O2: 82.176 | P2: 3.68 | Q2: 58.82
A3: 18768943 | B3: 997529 | C3: HR panty fant D formes | H3: CN61152200 | I3: 5 | J3: 4 | K3: 20 | L3: 1.48 | M3: 1.332 | N3: 0.617 | O3: 12.34 | P3: 1.86 | Q3: 37.2 | T3: Colisage | U3: #Colis | V3: #Pces | W3: Poids Brut | X3: Poids Net | Y3: Vol. Pce | Z3: Vol.Total | AA3: PA Unitaire | AB3: PA Global
A4: 18768943 | B4: 991982 | C4: PR 0CM4 CO ULTRA RESIST TRANSP 20 D NOIR | H4: CN61152200 | I4: 12 | J4: 3 | K4: 36 | L4: 1.86 | M4: 1.674 | N4: 0.633 | O4: 22.776 | P4: 4.01 | Q4: 144.36 | S4: CN64029910 | T4: 17 | U4: 74 | V4: 84 | W4: 28.927 | X4: 26.039 | Y4: 39.81 | Z4: 489.808 | AA4: 38.65 | AB4: 383.49
A5: 18768943 | B5: 709775 | C5: HR panty Golden Lady liberté abs silhou | H5: IT61152200 | I5: 12 | J5: 3 | K5: 36 | L5: 2.352 | M5: 2.117 | N5: 0.76 | O5: 27.36 | P5: 3.71 | Q5: 133.56 | S5: CN61152200 | T5: 17 | U5: 7 | V5: 56 | W5: 3.34 | X5: 3.006 | Y5: 1.25 | Z5: 35.116 | AA5: 5.87 | AB5: 181.56
A6: 18768943 | B6: 793513 | C6: HR panty fant D POIS | H6: CN61152100 | I6: 4 | J6: 4 | K6: 16 | L6: 1.14 | M6: 1.026 | N6: 0.781 | O6: 12.496 | P6: 1.67 | Q6: 26.64 | S6: IT61152200 | T6: 12 | U6: 3 | V6: 36 | W6: 2.352 | X6: 2.117 | Y6: 0.76 | Z6: 27.36 | AA6: 3.71 | AB6: 133.56
A7: 18768943 | B7: 723185 | C7: HR Ultra fine Hebdo 4 paires 42/43 | E7: 3031446805734 | H7: BE64069050 | I7: 3 | J7: 1 | K7: 3 | L7: 0.234 | M7: 0.211 | N7: 1 | O7: 3 | P7: 2.71 | Q7: 8.13 | S7: CN61152100 | T7: 13 | U7: 6 | V7: 25 | W7: 2.713 | X7: 2.442 | Y7: 3.343 | Z7: 24.88 | AA7: 5.2 | AB7: 42.89
A8: 18768943 | B8: 996593 | C8: HR ULTRA FINE HEBDO 2 PAIRES 38/39 | E8: 3031446805765 | H8: BE64069050 | I8: 3 | J8: 1 | K8: 3 | L8: 0.186 | M8: 0.167 | N8: 0.75 | O8: 2.25 | P8: 1.39 | Q8: 4.17 | S8: BE64069050 | T8: 18 | U8: 6 | V8: 18 | W8: 1.161 | X8: 1.045 | Y8: 4.918 | Z8: 14.754 | AA8: 13.02 | AB8: 39.06
A9: 18768943 | B9: 929409 | C9: HR Protection froid 38/39 | E9: 3031446801743 | H9: BE64069050 | I9: 3 | J9: 1 | K9: 3 | L9: 0.084 | M9: 0.076 | N9: 0.418 | O9: 1.254 | P9: 2.11 | Q9: 6.33 | S9: ES64041910 | T9: 5 | U9: 14 | V9: 27 | W9: 17.587 | X9: 15.828 | Y9: 12.817 | Z9: 114.739 | AA9: 12.22 | AB9: 120.56
A10: 18768943 | B10: 723182 | C10: HR Ultra fine Hebdo 4 paires 40/41 | E10: 3031446805727 | H10: BE64069050 | I10: 3 | J10: 1 | K10: 3 | L10: 0.219 | M10: 0.197 | N10: 1 | O10: 3 | P10: 2.71 | Q10: 8.13 | S10: BE48211010 | T10: 1 | U10: 5 | V10: 5 | W10: 0.15 | X10: 0.135 | Y10: 0.157 | Z10: 0.785 | AA10: 2 | AB10: 10
A11: 18768943 | B11: 723168 | C11: HR Ultra fine Hebdo 4 paires 44/45 | E11: 3031446805741 | H11: BE64069050 | I11: 3 | J11: 1 | K11: 3 | L11: 0.252 | M11: 0.227 | N11: 1 | O11: 3 | P11: 2.71 | Q11: 8.13 | S11: DE04015011 | T11: 1 | U11: 5 | V11: 5 | W11: 1.145 | X11: 1.031 | Y11: 0.746 | Z11: 3.73 | AA11: 0.58 | AB11: 2.9
A12: 18768943 | B12: 996600 | C12: HR ULTRA FINE HEBDO 2 PAIRES 36/37 | E12: 3031446805758 | H12: BE64069050 | I12: 3 | J12: 1 | K12: 3 | L12: 0.186 | M12: 0.167 | N12: 0.75 | O12: 2.25 | P12: 1.39 | Q12: 4.17 | S12: BE48219010 | T12: 1 | U12: 1 | V12: 1 | W12: 0.01 | X12: 0.009 | Y12: 0.45 | Z12: 0.45 | AA12: 11.02 | AB12: 11.02
A13: 18768943 | B13: 763302 | C13: HR SS-GENE DB COTON BIO NOIR 40/46 | H13: ES64041910 | I13: 2 | J13: 7 | K13: 14 | L13: 9.12 | M13: 8.208 | N13: 4.341 | O13: 60.774 | P13: 4.55 | Q13: 63.7 | S13: FR48191000 | T13: 10 | U13: 5 | V13: 50 | W13: 10 | X13: 9 | Y13: 8.55 | Z13: 427.5 | AA13: 2.58 | AB13: 129
A14: 18768943 | B14: 763301 | C14: HR SS-GENE DB LAINE BIO NOIR 40/46 | H14: ES64041910 | I14: 2 | J14: 6 | K14: 12 | L14: 7.872 | M14: 7.084 | N14: 4.135 | O14: 49.624 | P14: 4.47 | Q14: 53.66 | S14: BE19053199 | T14: 1 | U14: 5 | V14: 5 | W14: 3.13 | X14: 2.817 | Y14: 2.97 | Z14: 14.85 | AA14: 2.85 | AB14: 14.25
A15: 18768943 | B15: 905233 | C15: HR Sabot injecté db chaud Marine 41/46 | H15: CN64029910 | I15: 1 | J15: 16 | K15: 16 | L15: 5.637 | M15: 5.074 | N15: 6.918 | O15: 110.68 | P15: 4.04 | Q15: 64.62 | S15: FR39232100 | T15: 25 | U15: 3 | V15: 75 | W15: 25.125 | X15: 22.613 | Y15: 3 | Z15: 225 | AA15: 1.22 | AB15: 91.5
A16: 18768943 | B16: 905234 | C16: HR Sabot injecté db chaud Noir 36/41 | H16: CN64029910 | I16: 1 | J16: 12 | K16: 12 | L16: 3.21 | M16: 2.891 | N16: 5.036 | O16: 60.428 | P16: 3.08 | Q16: 36.96 | S16: CN33030010 | T16: 1 | U16: 2 | V16: 2 | W16: 2.424 | X16: 2.182 | Y16: 4 | Z16: 8 | AA16: 1.83 | AB16: 3.66
A17: 18768943 | B17: 905231 | C17: HR Sabot injecté db chaud Noir 41/46 | H17: CN64029910 | I17: 1 | J17: 16 | K17: 16 | L17: 5.496 | M17: 4.947 | N17: 6.902 | O17: 110.424 | P17: 3.66 | Q17: 58.51 | S17: ES33043000 | T17: 1 | U17: 5 | V17: 5 | W17: 1.335 | X17: 1.202 | Y17: 0.507 | Z17: 2.535 | AA17: 0.69 | AB17: 3.45
A18: 18768943 | B18: 905235 | C18: HR Sabot injecté db chaud Gris 36/41 | H18: CN64029910 | I18: 1 | J18: 12 | K18: 12 | L18: 3.226 | M18: 2.905 | N18: 5.198 | O18: 62.38 | P18: 3.25 | Q18: 38.94 | S18: BD62046390 | T18: 1 | U18: 1 | V18: 1 | W18: 0.471 | X18: 0.424 | Y18: 2.533 | Z18: 2.533 | AA18: 7.47 | AB18: 7.47
A19: 18832507 | B19: 901451 | C19: BROCHURE D'ACCUEIL | H19: BE48211010 | I19: 1 | J19: 5 | K19: 5 | L19: 0.15 | M19: 0.135 | N19: 0.157 | O19: 0.785 | P19: 2 | Q19: 10 | S19: CN39262000 | T19: 12 | U19: 7 | V19: 14 | W19: 0.818 | X19: 0.737 | Y19: 1.442 | Z19: 2.904 | AA19: 5.54 | AB19: 12.8
A20: 18832507 | B20: 900850 | C20: EVERYDAY CREME A CAFE (CUPS) 20 X 10 GR | E20: 5400141167900 | H20: DE04015011 | I20: 1 | J20: 5 | K20: 5 | L20: 1.145 | M20: 1.031 | N20: 0.746 | O20: 3.73 | P20: 0.58 | Q20: 2.9 | S20: BD62046290 | T20: 2 | U20: 3 | V20: 3 | W20: 1.74 | X20: 1.566 | Y20: 5.75 | Z20: 8.5 | AA20: 15.33 | AB20: 22.73
A21: 18832507 | B21: 900216 | C21: B/100 FEUILLES ETIQUET. PALETTE POUBELLE | H21: BE48219010 | I21: 1 | J21: 1 | K21: 1 | L21: 0.01 | M21: 0.009 | N21: 0.45 | O21: 0.45 | P21: 11.02 | Q21: 11.02 | S21: IN61152900 | T21: 2 | U21: 1 | V21: 2 | W21: 0.334 | X21: 0.301 | Y21: 1.386 | Z21: 2.772 | AA21: 2.58 | AB21: 5.16
A22: 18832507 | B22: 900774 | C22: CARTON AMERICAIN | H22: FR48191000 | I22: 10 | J22: 5 | K22: 50 | L22: 10 | M22: 9 | N22: 8.55 | O22: 427.5 | P22: 2.58 | Q22: 129 | S22: IN61142000 | T22: 2 | U22: 1 | V22: 2 | W22: 0.352 | X22: 0.317 | Y22: 1.176 | Z22: 2.352 | AA22: 2.55 | AB22: 5.1
A23: 18832507 | B23: 901050 | C23: BONI ASSORTIMENT MELANGE 500GR | H23: BE19053199 | I23: 1 | J23: 5 | K23: 5 | L23: 3.13 | M23: 2.817 | N23: 2.97 | O23: 14.85 | P23: 2.85 | Q23: 14.25 | S23: BD61109090 | T23: 56 | U23: 18 | V23: 60 | W23: 16.601 | X23: 14.941 | Y23: 41.609 | Z23: 160.584 | AA23: 69.61 | AB23: 306.57
A24: 18832507 | B24: 900781 | C24: MAXI SACS | H24: FR39232100 | I24: 25 | J24: 3 | K24: 75 | L24: 25.125 | M24: 22.613 | N24: 3 | O24: 225 | P24: 1.22 | Q24: 91.5 | S24: IN61091000 | T24: 52 | U24: 11 | V24: 58 | W24: 10.234 | X24: 9.21 | Y24: 15.041 | Z24: 98.02 | AA24: 31.95 | AB24: 207.82
A25: 18832517 | B25: 915273 | C25: EDP 50ML. ORIENTAL | E25: 8715658440048 | H25: CN33030010 | I25: 1 | J25: 2 | K25: 2 | L25: 2.424 | M25: 2.182 | N25: 4 | O25: 8 | P25: 1.83 | Q25: 3.66 | S25: PK61101990 | T25: 2 | U25: 1 | V25: 2 | W25: 0.86 | X25: 0.774 | Y25: 3.52 | Z25: 7.04 | AA25: 4.77 | AB25: 9.54
A26: 18832517 | B26: 283973 | C26: BYPHASSE DISSOLVANT 250ML ESSENTIALS | E26: 8436097092703 | F26: 8437005723306 | G26: 8436097093984 | H26: ES33043000 | I26: 1 | J26: 5 | K26: 5 | L26: 1.335 | M26: 1.202 | N26: 0.507 | O26: 2.535 | P26: 0.69 | Q26: 3.45 | S26: CN61103010 | T26: 13 | U26: 3 | V26: 13 | W26: 3.146 | X26: 2.831 | Y26: 8.442 | Z26: 34.152 | AA26: 17.42 | AB26: 76.52
A27: 18832651 | B27: 700322 | C27: PR JEANS REGULAR FIT DENIM NOIR | H27: BD62046390 | I27: 1 | J27: 1 | K27: 1 | L27: 0.471 | M27: 0.424 | N27: 2.533 | O27: 2.533 | P27: 7.47 | Q27: 7.47 | S27: HK61046900 | T27: 1 | U27: 2 | V27: 2 | W27: 0.592 | X27: 0.533 | Y27: 2.285 | Z27: 4.57 | AA27: 3.17 | AB27: 6.34
A28: 18832651 | B28: 991150 | C28: PR CEINT DGT NOIR Silver | H28: CN39262000 | I28: 2 | J28: 1 | K28: 2 | L28: 0.244 | M28: 0.22 | N28: 0.442 | O28: 0.884 | P28: 1.05 | Q28: 2.1 | S28: BD62034231 | T28: 4 | U28: 4 | V28: 4 | W28: 2.187 | X28: 1.969 | Y28: 9.445 | Z28: 9.445 | AA28: 27.83 | AB28: 27.83
A29: 18832651 | B29: 659963 | C29: PR PANT DROIT STRETCH GRIS | H29: BD62046290 | I29: 1 | J29: 1 | K29: 1 | L29: 0.497 | M29: 0.447 | N29: 3 | O29: 3 | P29: 7.93 | Q29: 7.93 | S29: IN61034900 | T29: 3 | U29: 3 | V29: 3 | W29: 0.816 | X29: 0.734 | Y29: 5.76 | Z29: 5.76 | AA29: 8.13 | AB29: 8.13
A30: 18832651 | B30: 635597 | C30: PR LEGGING LONG NOIR | H30: IN61152900 | I30: 2 | J30: 1 | K30: 2 | L30: 0.334 | M30: 0.301 | N30: 1.386 | O30: 2.772 | P30: 2.58 | Q30: 5.16 | S30: PK61101910 | T30: 26 | U30: 6 | V30: 26 | W30: 10.517 | X30: 9.465 | Y30: 14.809 | Z30: 48.539 | AA30: 36.25 | AB30: 158.05
A31: 18832651 | B31: 942303 | C31: HR LEGGING DARK GREY MEL | H31: IN61142000 | I31: 2 | J31: 1 | K31: 2 | L31: 0.352 | M31: 0.317 | N31: 1.176 | O31: 2.352 | P31: 2.55 | Q31: 5.1 | S31: CN61152900 | T31: 5 | U31: 12 | V31: 12 | W31: 0.764 | X31: 0.687 | Y31: 2.496 | Z31: 5.028 | AA31: 4.95 | AB31: 11.74
A32: 18832651 | B32: 700245 | C32: HR Cardigan Polar ftte turquoise | H32: BD61109090 | I32: 1 | J32: 1 | K32: 1 | L32: 0.136 | M32: 0.122 | N32: 1.8 | O32: 1.8 | P32: 2.86 | Q32: 2.86 | S32: CN61159500 | T32: 30 | U32: 5 | V32: 42 | W32: 5.232 | X32: 4.709 | Y32: 3.914 | Z32: 37.156 | AA32: 5.66 | AB32: 61.12
A33: 18832651 | B33: 700243 | C33: HR Cardigan Polar ftte bleu nuit | H33: BD61109090 | I33: 1 | J33: 1 | K33: 1 | L33: 0.204 | M33: 0.184 | N33: 2.4 | O33: 2.4 | P33: 2.93 | Q33: 2.93 | S33: PL61152100 | T33: 11 | U33: 3 | V33: 11 | W33: 0.709 | X33: 0.638 | Y33: 1.869 | Z33: 7.021 | AA33: 3.07 | AB33: 11.41
A34: 18832651 | B34: 700247 | C34: HR Cardigan Polar fille rose | H34: BD61109090 | I34: 1 | J34: 1 | K34: 1 | L34: 0.333 | M34: 0.3 | N34: 2.666 | O34: 2.666 | P34: 3.6 | Q34: 3.6 | S34: CN61082100 | T34: 18 | U34: 6 | V34: 20 | W34: 1.607 | X34: 1.447 | Y34: 2.848 | Z34: 12.637 | AA34: 6.71 | AB34: 33.75
A35: 18832651 | B35: 380893 | C35: PR tshirt fines brides cot-ea noir | H35: IN61091000 | I35: 2 | J35: 1 | K35: 2 | L35: 0.224 | M35: 0.202 | N35: 1.2 | O35: 2.4 | P35: 1.03 | Q35: 2.06 | S35: CN61089200 | T35: 6 | U35: 3 | V35: 6 | W35: 0.462 | X35: 0.416 | Y35: 1.797 | Z35: 3.594 | AA35: 4.31 | AB35: 8.62
A36: 18832651 | B36: 991151 | C36: PR CEINT DGT CAMEL Gold | H36: CN39262000 | I36: 2 | J36: 1 | K36: 2 | L36: 0.24 | M36: 0.216 | N36: 0.442 | O36: 0.884 | P36: 1.05 | Q36: 2.1 | S36: PL61152200 | T36: 4 | U36: 1 | V36: 4 | W36: 0.3 | X36: 0.27 | Y36: 0.541 | Z36: 2.164 | AA36: 1.22 | AB36: 4.88
A37: 18832651 | B37: 745081 | C37: PR CARDIGAN MOLLETON VIEUX ROSE | H37: PK61101990 | I37: 2 | J37: 1 | K37: 2 | L37: 0.86 | M37: 0.774 | N37: 3.52 | O37: 7.04 | P37: 4.77 | Q37: 9.54 | S37: CN61082200 | T37: 18 | U37: 6 | V37: 20 | W37: 1.705 | X37: 1.533 | Y37: 0.833 | Z37: 1.531 | AA37: 9.93 | AB37: 53.33
A38: 18832651 | B38: 380904 | C38: HR Polar cintré full zip NOIR | H38: CN61103010 | I38: 1 | J38: 1 | K38: 1 | L38: 0.35 | M38: 0.315 | N38: 3.3 | O38: 3.3 | P38: 5.6 | Q38: 5.6 | S38: CN61153090 | T38: 4 | U38: 1 | V38: 4 | W38: 0.248 | X38: 0.223 | Y38: 0.496 | Z38: 1.984 | AA38: 1.17 | AB38: 4.68
... A58: 18832651 | B58: 707862 | C58: HR Collant micro Fille LiLi Marine | H58: PL61152100 | I58: 3 | J58: 1 | K58: 3 | L58: 0.129 | M58: 0.116 | N58: 0.455 | O58: 1.365 | P58: 0.87 | Q58: 2.61 | S58: NL48030090 | T58: 1 | U58: 6 | V58: 6 | W58: 0.33 | X58: 0.297 | Y58: 0.545 | Z58: 3.27 | AA58: 0.59 | AB58: 3.54
A59: 18832651 | B59: 991176 | C59: PT lot 3 culottes Frozen | E59: 8720193921013 | H59: CN61082100 | I59: 12 | J59: 1 | K59: 12 | L59: 0.852 | M59: 0.767 | N59: 0.585 | O59: 7.02 | P59: 1.78 | Q59: 21.36 | S59: SY34011900 | T59: 1 | U59: 2 | V59: 2 | W59: 2.306 | X59: 2.075 | Y59: 4.333 | Z59: 8.666 | AA59: 10.02 | AB59: 20.04
...

Sheet Séparer
H1: Code | I1: Origine | J1: Colisage | K1: #Colis | L1: #Pces | M1: Valeur Addition | N1: Poids Brut | O1: Poids Net | P1: Vol. Pce | Q1: Vol.Total | R1: PA Global
H2: 04015011 | I2: DE | J2: 1 | K2: 5 | L2: 5 | M2: =LOOKUP(H2,$W$4:$W$192,Séparer!$X$4:$X$192) -> 0 | N2: 1.145 | O2: 1.031 | P2: 0.746 | Q2: 3.73 | R2: 2.9
H3: 17049061 | I3: IE | J3: 16 | K3: 1 | L3: 16 | M3: =LOOKUP(H3,$W$4:$W$192,Séparer!$X$4:$X$192) -> 0 | N3: 1.04 | O3: 0.936 | P3: 0.111 | Q3: 1.776 | R3: 19.36
H4: 17049065 | I4: BE | J4: 115 | K4: 14 | L4: 227 | M4: =LOOKUP(H4,$W$4:$W$192,Séparer!$X$4:$X$192) -> 0 | N4: 30.596 | O4: 27.536 | P4: 4.305 | Q4: 149.463 | R4: 153.84 | W4: 04015011
H5: 17049065 | I5: ES | J5: 33 | K5: 4 | L5: 44 | M5: =LOOKUP(H5,$W$4:$W$192,Séparer!$X$4:$X$192) -> 0 | N5: 4.631 | O5: 4.168 | P5: 1.512 | Q5: 22.044 | R5: 31.68 | W5: 17049061
H6: 17049065 | I6: CN | J6: 24 | K6: 2 | L6: 24 | M6: =LOOKUP(H6,$W$4:$W$192,Séparer!$X$4:$X$192) -> 0 | N6: 6.6 | O6: 5.94 | P6: 5.4 | Q6: 64.8 | R6: 61.2 | W6: 17049065 | X6: 0
H7: 17049071 | I7: BE | J7: 6 | K7: 1 | L7: 6 | M7: =LOOKUP(H7,$W$4:$W$192,Séparer!$X$4:$X$192) -> 0 | N7: 1.476 | O7: 1.328 | P7: 0.884 | Q7: 5.304 | R7: 8.04 | W7: 17049071 | X7: 0
H8: 17049071 | I8: CN | J8: 2 | K8: 28 | L8: 28 | M8: =LOOKUP(H8,$W$4:$W$192,Séparer!$X$4:$X$192) -> 0 | N8: 56 | O8: 50.4 | P8: 20.202 | Q8: 282.828 | R8: 19.88 | W8: 18063100 | X8: 0
H9: 18063100 | I9: DE | J9: 6 | K9: 6 | L9: 104 | M9: =LOOKUP(H9,$W$4:$W$192,Séparer!$X$4:$X$192) -> 0 | N9: 46.384 | O9: 41.746 | P9: 14.744 | Q9: 247.392 | R9: 463.04 | W9: 18069019 | X9: 0
H10: 18069019 | I10: DE | J10: 2 | K10: 2 | L10: 54 | M10: =LOOKUP(H10,$W$4:$W$192,Séparer!$X$4:$X$192) -> 0 | N10: 12.042 | O10: 10.838 | P10: 2.666 | Q10: 71.982 | R10: 135.54 | W10: 18069031 | X10: 0
H11: 18069019 | I11: IT | J11: 2 | K11: 2 | L11: 60 | M11: =LOOKUP(H11,$W$4:$W$192,Séparer!$X$4:$X$192) -> 0 | N11: 3.6 | O11: 3.24 | P11: 0.198 | Q11: 5.94 | R11: 27 | W11: 18069039 | X11: 0
H12: 18069019 | I12: BE | J12: 4 | K12: 4 | L12: 176 | M12: =LOOKUP(H12,$W$4:$W$192,Séparer!$X$4:$X$192) -> 0 | N12: 15.952 | O12: 14.356 | P12: 1.514 | Q12: 72.176 | R12: 334.72 | W12: 18069060 | X12: 0
H13: 18069019 | I13: CH | J13: 28 | K13: 2 | L13: 28 | M13: =LOOKUP(H13,$W$4:$W$192,Séparer!$X$4:$X$192) -> 0 | N13: 5.376 | O13: 4.838 | P13: 3.7 | Q13: 51.8 | R13: 58.8 | W13: 19053119 | X13: 0
H14: 18069031 | I14: BE | J14: 10 | K14: 10 | L14: 208 | M14: =LOOKUP(H14,$W$4:$W$192,Séparer!$X$4:$X$192) -> 0 | N14: 38.076 | O14: 34.268 | P14: 14.212 | Q14: 314.768 | R14: 804.56 | W14: 19053199 | X14: 0
H15: 18069031 | I15: PL | J15: 4 | K15: 4 | L15: 176 | M15: =LOOKUP(H15,$W$4:$W$192,Séparer!$X$4:$X$192) -> 0 | N15: 7.656 | O15: 6.89 | P15: 1.606 | Q15: 73.112 | R15: 201.28 | W15: 20052020 | X15: 0
H16: 18069039 | I16: DE | J16: 64 | K16: 2 | L16: 64 | M16: =LOOKUP(H16,$W$4:$W$192,Séparer!$X$4:$X$192) -> 0 | N16: 9.984 | O16: 8.986 | P16: 1.874 | Q16: 59.968 | R16: 46.08 | W16: 21069051 | X16: 0
H17: 18069060 | I17: IT | J17: 128 | K17: 2 | L17: 128 | M17: =LOOKUP(H17,$W$4:$W$192,Séparer!$X$4:$X$192) -> 0 | N17: 9.088 | O17: 8.18 | P17: 0.25 | Q17: 16 | R17: 69.12 | W17: 21069059 | X17: 0
H18: 19053119 | I18: BE | J18: 20 | K18: 1 | L18: 20 | M18: =LOOKUP(H18,$W$4:$W$192,Séparer!$X$4:$X$192) -> 0 | N18: 1.34 | O18: 1.206 | P18: 0.228 | Q18: 4.56 | R18: 8.8 | W18: 22011090 | X18: LTR
H19: 19053199 | I19: BE | J19: 1 | K19: 5 | L19: 5 | M19: =LOOKUP(H19,$W$4:$W$192,Séparer!$X$4:$X$192) -> 0 | N19: 3.13 | O19: 2.817 | P19: 2.97 | Q19: 14.85 | R19: 14.25 | W19: 22021000 | X19: LTR
H20: 20052020 | I20: FR | J20: 20 | K20: 2 | L20: 20 | M20: =LOOKUP(H20,$W$4:$W$192,Séparer!$X$4:$X$192) -> 0 | N20: 3.1 | O20: 2.79 | P20: 5.64 | Q20: 56.4 | R20: 25.9 | W20: 23091090 | X20: 0
H21: 21069051 | I21: CH | J21: 1 | K21: 2 | L21: 2 | M21: =LOOKUP(H21,$W$4:$W$192,Séparer!$X$4:$X$192) -> 0 | N21: 0.08 | O21: 0.072 | P21: 0.239 | Q21: 0.478 | R21: 2.8 | W21: 23099096 | X21: 0
H22: 21069059 | I22: CN | J22: 48 | K22: 2 | L22: 48 | M22: =LOOKUP(H22,$W$4:$W$192,Séparer!$X$4:$X$192) -> 0 | N22: 6.168 | O22: 5.551 | P22: 0.765 | Q22: 18.36 | R22: 77.76 | W22: 28363000 | X22: 0
H23: 22011090 | I23: BE | J23: 6 | K23: 2 | L23: 12 | M23: =LOOKUP(H23,$W$4:$W$192,Séparer!$X$4:$X$192) -> LTR | N23: 6.3 | O23: 5.67 | P23: 0.937 | Q23: 11.244 | R23: 4.68 | W23: 30051000 | X23: 0
H24: 22021000 | I24: NL | J24: 12 | K24: 1 | L24: 12 | M24: =LOOKUP(H24,$W$4:$W$192,Séparer!$X$4:$X$192) -> LTR | N24: 4.74 | O24: 4.266 | P24: 0.52 | Q24: 6.24 | R24: 9.84 | W24: 33012949 | X24: 0
H25: 22021000 | I25: GB | J25: 24 | K25: 1 | L25: 24 | M25: =LOOKUP(H25,$W$4:$W$192,Séparer!$X$4:$X$192) -> LTR | N25: 8.952 | O25: 8.057 | P25: 0.51 | Q25: 12.24 | R25: 15.6 | W25: 33012991 | X25: 0
H26: 22021000 | I26: BE | J26: 24 | K26: 1 | L26: 24 | M26: =LOOKUP(H26,$W$4:$W$192,Séparer!$X$4:$X$192) -> LTR | N26: 13.104 | O26: 11.794 | P26: 0.695 | Q26: 16.68 | R26: 29.76 | W26: 33021010 | X26: 0
H27: 23091090 | I27: FR | J27: 1 | K27: 5 | L27: 5 | M27: =LOOKUP(H27,$W$4:$W$192,Séparer!$X$4:$X$192) -> 0 | N27: 0.58 | O27: 0.522 | P27: 0.756 | Q27: 3.78 | R27: 8.45 | W27: 33030010 | X27: 0
H28: 23099096 | I28: HU | J28: 11 | K28: 5 | L28: 14 | M28: =LOOKUP(H28,$W$4:$W$192,Séparer!$X$4:$X$192) -> 0 | N28: 7.58 | O28: 6.822 | P28: 5.978 | Q28: 26.18 | R28: 18.16 | W28: 33030090 | X28: 0
H29: 23099096 | I29: BE | J29: 2 | K29: 5 | L29: 9 | M29: =LOOKUP(H29,$W$4:$W$192,Séparer!$X$4:$X$192) -> 0 | N29: 23.724 | O29: 21.351 | P29: 7.84 | Q29: 43.68 | R29: 20.78 | W29: 33043000 | X29: 0
H30: 28363000 | I30: BE | J30: 7 | K30: 4 | L30: 9 | M30: =LOOKUP(H30,$W$4:$W$192,Séparer!$X$4:$X$192) -> 0 | N30: 6.756 | O30: 6.08 | P30: 2.948 | Q30: 11.517 | R30: 21.27 | W30: 33049900 | X30: 0
H31: 30051000 | I31: ES | J31: 1 | K31: 4 | L31: 4 | M31: =LOOKUP(H31,$W$4:$W$192,Séparer!$X$4:$X$192) -> 0 | N31: 0.104 | O31: 0.094 | P31: 0.269 | Q31: 1.076 | R31: 8.72 | W31: 33051000 | X31: 0
... H41: 33049900 | I41: CN | J41: 4 | K41: 200 | L41: 200 | M41: =LOOKUP(H41,$W$4:$W$192,Séparer!$X$4:$X$192) -> 0 | N41: 27.84 | O41: 25.056 | P41: 0.692 | Q41: 34.76 | R41: 192 | W41: 39232100 | X41: 0
H42: 33051000 | I42: FR | J42: 2 | K42: 4 | L42: 4 | M42: =LOOKUP(H42,$W$4:$W$192,Séparer!$X$4:$X$192) -> 0 | N42: 4.658 | O42: 4.192 | P42: 4.355 | Q42: 8.71 | R42: 7.9 | W42: 39233010 | X42: NAR
H43: 33059000 | I43: FR | J43: 1 | K43: 2 | L43: 2 | M43: =LOOKUP(H43,$W$4:$W$192,Séparer!$X$4:$X$192) -> 0 | N43: 1.136 | O43: 1.022 | P43: 0.96 | Q43: 1.92 | R43: 4.64 | W43: 39241000 | X43: 0
H44: 33073000 | I44: CN | J44: 12 | K44: 2 | L44: 12 | M44: =LOOKUP(H44,$W$4:$W$192,Séparer!$X$4:$X$192) -> 0 | N44: 0.24 | O44: 0.216 | P44: 3.5 | Q44: 21 | R44: 79.8 | W44: 39249000 | X44: 0
H45: 33074900 | I45: CN | J45: 2 | K45: 5 | L45: 5 | M45: =LOOKUP(H45,$W$4:$W$192,Séparer!$X$4:$X$192) -> 0 | N45: 1.24 | O45: 1.116 | P45: 4.977 | Q45: 7.812 | R45: 9.63 | W45: 39261000 | X45: 0
H46: 33079000 | I46: FR | J46: 2 | K46: 6 | L46: 6 | M46: =LOOKUP(H46,$W$4:$W$192,Séparer!$X$4:$X$192) -> 0 | N46: 1.46 | O46: 1.314 | P46: 0.876 | Q46: 2.674 | R46: 23.08 | W46: 39262000 | X46: 0
H47: 34011900 | I47: SY | J47: 1 | K47: 2 | L47: 2 | M47: =LOOKUP(H47,$W$4:$W$192,Séparer!$X$4:$X$192) -> 0 | N47: 2.306 | O47: 2.075 | P47: 4.333 | Q47: 8.666 | R47: 20.04 | W47: 39264000 | X47: 0
H48: 34013000 | I48: FR | J48: 1 | K48: 2 | L48: 2 | M48: =LOOKUP(H48,$W$4:$W$192,Séparer!$X$4:$X$192) -> 0 | N48: 2.36 | O48: 2.124 | P48: 2.08 | Q48: 4.16 | R48: 3.96 | W48: 39269097 | X48: 0
H49: 34013000 | I49: ES | J49: 1 | K49: 3 | L49: 3 | M49: =LOOKUP(H49,$W$4:$W$192,Séparer!$X$4:$X$192) -> 0 | N49: 1.764 | O49: 1.587 | P49: 1.155 | Q49: 3.465 | R49: 2.55 | W49: 40169200 | X49: 0
...

Sheet Valeur Additionelle
D3: NBR | E3: Code | F3: Valeur/Unité
D6: 1 | E6: 04015011 | F6: 0
D7: 2 | E7: 17049061 | F7: 0
D8: 3 | E8: 17049065 | F8: 0
D9: 4 | E9: 17049071 | F9: 0
D10: 5 | E10: 18063100 | F10: 0
D11: 6 | E11: 18069019 | F11: 0
D12: 7 | E12: 18069031 | F12: 0
D13: 8 | E13: 18069039 | F13: 0
D14: 9 | E14: 18069060 | F14: 0
D15: 10 | E15: 19053119 | F15: 0
D16: 11 | E16: 19053199 | F16: 0
D17: 12 | E17: 20052020 | F17: 0
D18: 13 | E18: 21069051 | F18: 0
D19: 14 | E19: 21069059 | F19: 0
D20: 15 | E20: 22011090 | F20: LTR | G20: Regarder description pour le litrage
D21: 16 | E21: 22021000 | F21: LTR | G21: Regarder description pour le litrage
D22: 17 | E22: 23091090 | F22: 0
D23: 18 | E23: 23099096 | F23: 0
D24: 19 | E24: 28363000 | F24: 0
D25: 20 | E25: 30051000 | F25: 0
D26: 21 | E26: 33012949 | F26: 0
D27: 22 | E27: 33012991 | F27: 0
D28: 23 | E28: 33021010 | F28: 0
D29: 24 | E29: 33030010 | F29: 0
D30: 25 | E30: 33030090 | F30: 0
D31: 26 | E31: 33043000 | F31: 0
D32: 27 | E32: 33049900 | F32: 0
D33: 28 | E33: 33051000 | F33: 0
... D43: 38 | E43: 39232100 | F43: 0
D44: 39 | E44: 39233010 | F44: NAR | G44: Nombre de pièces
D45: 40 | E45: 39241000 | F45: 0
D46: 41 | E46: 39249000 | F46: 0
D47: 42 | E47: 39261000 | F47: 0
D48: 43 | E48: 39262000 | F48: 0
D49: 44 | E49: 39264000 | F49: 0
D50: 45 | E50: 39269097 | F50: 0
D51: 46 | E51: 40169200 | F51: 0
C52: 0.25 | D52: 47 | E52: 42010000 | F52: 0
D53: 48 | E53: 42022100 | F53: Nar | G53: Nombre de pièces
...

Sheet ETAPE
A4: Nouvel onglet | B4: 1 | C4: Copier les données brutes dans un seul fichier. NE PAS PRENDRE LES PALETTES
B5: 2 | C5: Vérifier si le total des données brutes = total des factures ( vérification par les totaux)
B6: 3 | C6: Supprimer les colonnes vides et inutiles
A7: Nouvel onglet | B7: 4 | C7: Combiner les codes et les origines avec la formule concaténer
C8: Faire une colonne avec la formule et une colonne avec la valeur obtenue
B9: 5 | C9: Supprimer les colonnes codes, origine et formule conca
B10: 6 | C10: Réduire les codes dans onglet données et consolider
C11: Référence = tableau Choisir case vide pour que le tableau se calcule (a coté)
A12: Nouvel onglet | B12: 7 | C12: Séparer de les codes et les origines
C13: Créer une colone vide pour code ou origine
C14: Utiliser fonction convertir dans onglet données
C15: Sélectionner l'ensemble des cellules à séparer puis utiliser fonction
B16: 8 | C16: Copier les données obtenues du tableau final dans le fichier infection ( pas sur le vierge !)
C17: Attention au valeur additionelle - s'adapter
C18: Faire une colonne pour la valeur additionelle et utiliser formule recherche ( Attention, peut-être pas assez fiable)
C19: Pour les valeurs autre que Nar ET NPP, prendre le volume total

Sheet Trafic - Résumé 
B1: Code Nomenclature | C1: Origine | D1: Devise | E1: Colisage | F1: Poids Brut | G1: Poids Net | H1: Valeur | I1: Valeur douane | J1: TVA | K1: N° Facture
A2: 1 | B2: ='[1]INTEGRA - Détails'!B3 -> 0 | C2: ='[1]INTEGRA - Détails'!B4 -> 0 | D2: =LOOKUP(K2,$H$17:$H$25,$K$17:$K$25) -> #N/A | F2: 2626.257 | G2: 2363.631 | H2: 24618.77
A3: 2 | B3: ='[1]INTEGRA - Détails'!D3 -> 0 | C3: ='[1]INTEGRA - Détails'!D4 -> 0 | D3: =LOOKUP(K3,$H$17:$H$25,$K$17:$K$25) -> #N/A | F3: 510
A4: 3 | B4: ='[1]INTEGRA - Détails'!F3 -> 0 | C4: ='[1]INTEGRA - Détails'!F4 -> 0 | D4: =LOOKUP(K4,$H$17:$H$25,$K$17:$K$25) -> #N/A
A5: 4 | B5: ='[1]INTEGRA - Détails'!H3 -> 0 | C5: ='[1]INTEGRA - Détails'!H4 -> 0 | D5: =LOOKUP(K5,$H$17:$H$25,$K$17:$K$25) -> #N/A
A6: 5 | B6: ='[1]INTEGRA - Détails'!J3 -> 0 | C6: ='[1]INTEGRA - Détails'!J4 -> 0 | D6: =LOOKUP(K6,$H$17:$H$25,$K$17:$K$25) -> #N/A
A7: 6 | B7: ='[1]INTEGRA - Détails'!L3 -> 0 | C7: ='[1]INTEGRA - Détails'!L4 -> 0 | D7: =LOOKUP(K7,$H$17:$H$25,$K$17:$K$25) -> #N/A
A8: 7 | B8: ='[1]INTEGRA - Détails'!N3 -> 0 | C8: ='[1]INTEGRA - Détails'!N4 -> 0 | D8: =LOOKUP(K8,$H$17:$H$25,$K$17:$K$25) -> #N/A
A9: 8 | B9: ='[1]INTEGRA - Détails'!P3 -> 0 | C9: ='[1]INTEGRA - Détails'!P4 -> 0 | D9: =LOOKUP(K9,$H$17:$H$25,$K$17:$K$25) -> #N/A
A10: 9 | B10: ='[1]INTEGRA - Détails'!R3 -> 0 | C10: ='[1]INTEGRA - Détails'!R4 -> 0 | D10: =LOOKUP(K10,$H$17:$H$25,$K$17:$K$25) -> #N/A
A11: 10 | B11: ='[1]INTEGRA - Détails'!T3 -> 0 | C11: ='[1]INTEGRA - Détails'!T4 -> 0 | D11: =LOOKUP(K11,$H$17:$H$25,$K$17:$K$25) -> #N/A
B13: TOTAL | E13: =SUM(E2:E12) -> 0 | F13: =SUM(F2:F12) -> 3136.257 | G13: =SUM(G2:G12) -> 2363.631 | H13: =SUM(H2:H11) -> 24618.77 | I13: =SUM(I2:I11) -> 0 | J13: =SUM(J2:J11) -> 0
B14: Total Colis | D14: =C14-E13 -> 0
B15: Poids Brut | C15: =455.518+1036.537+1134.202+68+221+221 -> 3136.257 | D15: =IF($F$13=$C$15,"OK","ERREUR") -> OK
B16: Poids à rajouter s/ last rubrique : | C16: =C15-F13 -> 0 | H16: N° Facture | I16: Valeur | J16: P. NET | K16: Devise
B17: Poids Net MRN | C17: =409.977+932.877+1020.777 -> 2363.631 | D17: =IF($G$13=$C$17,"OK","ERREUR") -> OK | E17: =C17-G13 -> 0 | H17: 90128373 | I17: 2922.32 | J17: 409.977
B18: N° Rubrique | C18: =COUNT(B2:B11) -> 10 | H18: 90128374 | I18: 10694.7 | J18: 932.877
B19: Valeur douane | C19: =LOOKUP(C18,B36:B55,C36:C55) -> 0 | H19: 90128376 | I19: 11001.75 | J19: 1020.777
B20: Changement TVA | C20: =LOOKUP(C18,B36:B55,E36:E55) -> 5
H26: Total | I26: =SUM(I17:I25) -> 24618.77 | J26: =SUM(J17:J25) -> 2363.631
I27: =IF(H13=I26,"OK","ERREUR") -> OK | J27: =IF(G13=J26,"OK","ERREUR") -> OK
I28: =I26-H13 -> 0 | J28: =J26-G13 -> 0
B34: SANS DROITS DE DOUANE
B35: Nombre de rubrique | C35: Valeur douane | E35: TVA | H35: Valeur douane | J35: TVA
B36: 1 | C36: 0 | E36: =50/B36 -> 50 | G36: 1 | H36: -400 | J36: 450
B37: 2 | C37: 0 | E37: =50/B37 -> 25 | G37: 2 | H37: -200 | J37: 225
B38: 3 | C38: 0 | E38: 10+20+20 | G38: 3 | H38: -150&-150&-100 | J38: 150
B39: 4 | C39: 0 | E39: =50/B39 -> 12.5 | G39: 4 | H39: -100 | J39: 3*100&150
B40: 5 | C40: 0 | E40: =50/B40 -> 10 | G40: 5 | H40: -80 | J40: 90
B41: 6 | C41: 0 | E41: 5*8+10 | G41: 6 | H41: 5*-60&-100 | J41: 75
B42: 7 | C42: 0 | E42: 6*7+8 | G42: 7 | H42: 6*-50&-100 | J42: 6*50&150
B43: 8 | C43: 0 | E43: =50/B43 -> 6.25 | G43: 8 | H43: -50 | J43: 7*50&100
B44: 9 | C44: 0 | E44: 8*5+10 | G44: 9 | H44: 8*-40&-80 | J44: 50
B45: 10 | C45: 0 | E45: =50/B45 -> 5 | G45: 10 | H45: -40 | J45: 45 | L45: =12*3 -> 36
B46: 11 | C46: 0 | E46: 10*4+10 | G46: 11 | H46: 10*-30 & -100 | J46: 10*40&50
B47: 12 | C47: 0 | E47: 11*4+6 | G47: 12 | H47: 11*-30 & -70 | J47: 11*30&120
B48: 13 | C48: 0 | E48: 12*3+14 | G48: 13 | H48: 12*-30 & -40 | J48: 12*30&90
B49: 14 | C49: 0 | E49: 13*3+11 | G49: 14 | H49: 13*-30 & -10 | J49: 13*30&60
B50: 15 | C50: 0 | E50: 14*3+8 | G50: 15 | H50: 14*-25 & -50 | J50: 30
B51: 16 | C51: 0 | E51: 15*3+5 | G51: 16 | H51: -25 | J51: 15*25 & 75
...
